Workbook

Sheet графика по среднему НПС
C1: январь | D1: февраль | E1: март | F1: апрель | G1: май | H1: июнь | I1: июль | J1: август | K1: сентябрь | L1: октябрь | M1: ноябрь | N1: декабрь | O1: средний за год
B2: Тренинги | C2: 92 | D2: 91 | E2: 87 | F2: 83 | G2: 82 | H2: 82 | I2: 84 | J2: 84 | K2: 83 | L2: 85 | M2: 86 | N2: 93 | O2: 86
B3: Фабрики процессов | C3: 60 | D3: 83 | E3: 90 | F3: 99 | G3: 87 | H3: 95 | I3: 88 | J3: 85 | K3: 76 | L3: 97 | M3: 88 | N3: 87 | O3: 86

Sheet Статистика НПС по тренингам
D3: Статистика NPS по тренингам за 2025 год
B5: Название тренинга | C5: январь | D5: февраль | E5: март | F5: апрель | G5: май | H5: июнь | I5: июль | J5: август | K5: сентябрь | L5: октябрь | M5: ноябрь | N5: декабрь | O5: средний НПС
A6: 1 модуль | B6: ОБП | C6: 92 | D6: 93 | E6: 88 | F6: 82 | G6: 73 | H6: 64 | I6: 80 | J6: 81 | K6: 82 | L6: 77 | O6: 81
B7: РПУ | C7: 89 | D7: 89 | E7: 81 | F7: 77 | G7: 77 | H7: 80 | I7: 80 | J7: 82 | K7: 80 | L7: 76 | O7: 82
B8: 5С | C8: 94 | D8: 94 | E8: 90 | F8: 83 | G8: 79 | H8: 85 | I8: 87 | J8: 89 | K8: 79 | L8: 87 | O8: 87
B9: Картирование | C9: 95 | D9: 95 | E9: 83 | F9: 88 | G9: 83 | H9: 83 | I9: 88 | J9: 87 | K9: 86 | L9: 95 | O9: 88
B10: ПА | C10: 91 | D10: 100 | E10: 87 | F10: 79 | G10: 77 | H10: 84 | I10: 85 | J10: 83 | K10: 86 | L10: 90 | O10: 86
A11: 2 модуль | B11: СР | D11: 80 | E11: 100 | F11: 86 | G11: 89 | H11: 90 | I11: 75 | J11: 86 | K11: 89 | L11: 84 | N11: 92 | O11: 87
B12: СМЕД | D12: 80 | G12: 100 | I12: 84 | L12: 86 | O12: 88
B13: АО | D13: 90 | F13: 100 | H13: 80 | I13: 92 | L13: 86 | O13: 90
B14: ОЕЕ | F14: 100 | G14: 100 | H14: 75 | I14: 94 | O14: 92
B15: МРП | F15: 100 | G15: 89 | H15: 94 | I15: 91 | J15: 78 | K15: 89 | L15: 89 | N15: 100 | O15: 90
A16: Фабрики | B16: ФП/ФОП | C16: 60 | D16: 83 | E16: 90 | F16: 99 | G16: 87 | H16: 95 | I16: 88 | J16: 85 | K16: 76 | L16: 97 | M16: 88 | N16: 87 | O16: 86

Sheet Статистика по тренерам
A1: Месяц | B1: День | C1: ФИО тренера | D1: Тренинг | E1: Предприятие | F1: NPS | G1: Средний NPS
A2: 1 | B2: 15 | C2: Басанцова Надежда | D2: РПУ | E2: ООО "ПО Лузар" | F2: 0.78 | G2: 88
A3: 1 | B3: 15 | C3: Басанцова Надежда | D3: 5С | E3: ООО "ПО Лузар" | F3: 0.88
A4: 1 | B4: 20 | C4: Басанцова Надежда | D4: Картирование | E4: ООО "ПО Лузар" | F4: 0.9
A5: 1 | B5: 20 | C5: Басанцова Надежда | D5: ПА | E5: ООО "ПО Лузар" | F5: 0.82
A6: 1 | B6: 31 | C6: Басанцова Надежда | D6: ОБП | E6: ООО "Старк-СПб" | F6: 1
A7: 1 | B7: 13 | C7: Туранов Кирилл | D7: ОБП | E7: ООО "ПО Лузар" | F7: 0.78 | G7: 96
A8: 1 | B8: 17 | C8: Туранов Кирилл | D8: ОБП | E8: ООО "Прогресс-СП" | F8: 1
A9: 1 | B9: 22 | C9: Туранов Кирилл | D9: РПУ | E9: ООО "Прогресс-СП" | F9: 1
A10: 1 | B10: 22 | C10: Туранов Кирилл | D10: 5С | E10: ООО "Прогресс-СП" | F10: 1
A11: 1 | B11: 29 | C11: Туранов Кирилл | D11: Картирование | E11: ООО "Прогресс-СП" | F11: 1
A12: 1 | B12: 29 | C12: Туранов Кирилл | D12: ПА | E12: ООО "Прогресс-СП" | F12: 1
A13: 2 | B13: 5 | C13: Басанцова Надежда | D13: РПУ | E13: ООО "Старк-СПб" | F13: 0.78 | G13: 91
A14: 2 | B14: 5 | C14: Басанцова Надежда | D14: 5С | E14: ООО "Старк-СПб" | F14: 1
A15: 2 | B15: 12 | C15: Басанцова Надежда | D15: Картирование | E15: ООО "Старк-СПб" | F15: 0.91
A16: 2 | B16: 12 | C16: Басанцова Надежда | D16: ПА | E16: ООО "Старк-СПб" | F16: 1
A17: 2 | B17: 25 | C17: Басанцова Надежда | D17: ОБП | E17: АО "ЛСР-Краны-Северо-Запад" | F17: 0.86
A18: 2 | B18: 14 | C18: Туранов Кирилл | D18: Картирование | E18: ООО "ГСП-Переработка" | F18: 1 | G18: 88
A19: 2 | B19: 20 | C19: Туранов Кирилл | D19: СР | E19: ООО "ПО Лузар" | F19: 0.8
A20: 2 | B20: 24 | C20: Туранов Кирилл | D20: АО | E20: ООО "ПО Лузар" | F20: 0.9
A21: 2 | B21: 24 | C21: Туранов Кирилл | D21: СМЕД | E21: ООО "ПО Лузар" | F21: 0.8
A22: 2 | B22: 11 | C22: Уваров Константин | D22: ОБП | E22: ООО "ГСП-Переработка" | F22: 1 | G22: 96
A23: 2 | B23: 12 | C23: Уваров Константин | D23: РПУ | E23: ООО "ГСП-Переработка" | F23: 1
A24: 2 | B24: 12 | C24: Уваров Константин | D24: 5С | E24: ООО "ГСП-Переработка" | F24: 0.88
A25: 3 | B25: 4 | C25: Хлебников Александр | D25: РПУ | E25: АО "ЛСР-Краны-Северо-Запад" | F25: 0.83 | G25: 90
A26: 3 | B26: 4 | C26: Хлебников Александр | D26: 5С | E26: АО "ЛСР-Краны-Северо-Запад" | F26: 1
A27: 3 | B27: 21 | C27: Хлебников Александр | D27: ОБП | E27: ООО "Авентин Инжиниринг" | F27: 1
A28: 3 | B28: 28 | C28: Хлебников Александр | D28: РПУ | E28: ООО "Авентин Инжиниринг" | F28: 0.88
A29: 3 | B29: 28 | C29: Хлебников Александр | D29: 5С | E29: ООО "Авентин Инжиниринг" | F29: 0.8
A30: 3 | B30: 14 | C30: Басанцова Надежда | D30: ОБП | E30: ООО "Фабрика счастья" | F30: 0.83 | G30: 83
A31: 3 | B31: 17 | C31: Басанцова Надежда | D31: РПУ | E31: ООО "Фабрика счастья" | F31: 0.73
A32: 3 | B32: 17 | C32: Басанцова Надежда | D32: ПА | E32: ООО "Фабрика счастья" | F32: 0.82
A33: 3 | B33: 18 | C33: Басанцова Надежда | D33: Картирование | E33: АО "ЛСР-Краны-Северо-Запад" | F33: 0.83
A34: 3 | B34: 18 | C34: Басанцова Надежда | D34: ПА | E34: АО "ЛСР-Краны-Северо-Запад" | F34: 1
A35: 3 | B35: 19 | C35: Басанцова Надежда | D35: Картирование | E35: ООО "Фабрика счастья" | F35: 0.83
A36: 3 | B36: 19 | C36: Басанцова Надежда | D36: ПА | E36: ООО "Фабрика счастья" | F36: 0.8
A37: 3 | B37: 27 | C37: Басанцова Надежда | D37: ОБП | E37: ООО "Красивый город" | F37: 0.8
A38: 3 | B38: 28 | C38: Туранов Кирилл | D38: СР | E38: ООО "Прогресс-СП" | F38: 1 | G38: 100
A39: 4 | B39: 1 | C39: Басанцова Надежда | D39: ОБП | E39: ООО "ДизайнИнвест" | F39: 0.81818182 | G39: 83
A40: 4 | B40: 2 | C40: Басанцова Надежда | D40: РПУ | E40: ООО "ДизайнИнвест" | F40: 0.71428571
...

Sheet Графика НПС по тренерам
B1: ФИО тренера | C1: январь | D1: февраль | E1: март | F1: апрель | G1: май | H1: июнь | I1: июль | J1: август | K1: сентябрь | L1: октябрь | M1: ноябрь | N1: декабрь | O1: средний NPS
B2: Васильева С.В. | F2: 100 | G2: 82 | H2: 75 | I2: 82 | J2: 81 | K2: 84 | L2: 84 | M2: 90 | O2: 85
B3: Басанцова Н.В. | C3: 88 | D3: 91 | E3: 83 | F3: 83 | G3: 81 | H3: 77 | I3: 84 | J3: 84 | K3: 84 | L3: 80 | M3: 86 | N3: 100 | O3: 85
B4: Туранов К.Д. | C4: 96 | D4: 88 | E4: 100 | F4: 85 | G4: 84 | H4: 76 | I4: 89 | J4: 74 | K4: 83 | L4: 92 | M4: 94 | O4: 87
B5: Уваров К.А. | D5: 96 | F5: 74 | H5: 85 | I5: 89 | J5: 78 | K5: 75 | L5: 87 | M5: 87 | N5: 93 | O5: 85
B6: Хлебников А.В. | E6: 90 | F6: 87 | G6: 83 | H6: 96 | I6: 77 | J6: 81 | K6: 82 | L6: 79 | M6: 62 | N6: 87 | O6: 82
B7: Чуприков С.О. | F7: 75 | G7: 75 | I7: 85 | J7: 92 | K7: 85 | L7: 60 | M7: 75 | O7: 78
B8: Осман А.А. | L8: 100 | M8: 78 | O8: 89
B9: Левкина Н.В. | J9: 96 | K9: 96 | L9: 100 | O9: 97

Sheet Итого за год
A1: 2 | B1: 2025 | C1: 1 | D1: 15 | E1: Басанцова Надежда | F1: РПУ | G1: ООО "ПО Лузар" | J1: 2025 год
A2: 3 | B2: 2025 | C2: 1 | D2: 15 | E2: Басанцова Надежда | F2: 5С | G2: ООО "ПО Лузар" | I2: № | J2: ФИО тренера | K2: Количество тренингов | L2: место в рейтинге
A3: 5 | B3: 2025 | C3: 1 | D3: 20 | E3: Басанцова Надежда | F3: Картирование | G3: ООО "ПО Лузар" | I3: 1 | J3: Басанцова Надежда | K3: 90 | L3: 1
A4: 6 | B4: 2025 | C4: 1 | D4: 20 | E4: Басанцова Надежда | F4: ПА | G4: ООО "ПО Лузар" | I4: 2 | J4: Васильева Светлана | K4: 53 | L4: 5
A5: 11 | B5: 2025 | C5: 1 | D5: 31 | E5: Басанцова Надежда | F5: ОБП | G5: ООО "Старк-СПб" | I5: 3 | J5: Лёвкина Наталья | K5: 8 | L5: 7
A6: 12 | B6: 2025 | C6: 2 | D6: 5 | E6: Басанцова Надежда | F6: РПУ | G6: ООО "Старк-СПб" | I6: 4 | J6: Туранов Кирилл | K6: 73 | L6: 4
A7: 13 | B7: 2025 | C7: 2 | D7: 5 | E7: Басанцова Надежда | F7: 5С | G7: ООО "Старк-СПб" | I7: 5 | J7: Уваров Константин | K7: 78 | L7: 2
A8: 15 | B8: 2025 | C8: 2 | D8: 12 | E8: Басанцова Надежда | F8: Картирование | G8: ООО "Старк-СПб" | I8: 6 | J8: Хлебников Александр | K8: 77 | L8: 3
A9: 16 | B9: 2025 | C9: 2 | D9: 12 | E9: Басанцова Надежда | F9: ПА | G9: ООО "Старк-СПб" | I9: 7 | J9: Чуприков Станислав | K9: 26 | L9: 6
A10: 23 | B10: 2025 | C10: 2 | D10: 25 | E10: Басанцова Надежда | F10: ОБП | G10: АО "ЛСР-Краны-Северо-Запад" | I10: 8 | J10: Осман Александра | K10: 5 | L10: 8
A11: 26 | B11: 2025 | C11: 3 | D11: 14 | E11: Басанцова Надежда | F11: ОБП | G11: ООО "Фабрика счастья"
A12: 27 | B12: 2025 | C12: 3 | D12: 17 | E12: Басанцова Надежда | F12: РПУ | G12: ООО "Фабрика счастья"
A13: 28 | B13: 2025 | C13: 3 | D13: 17 | E13: Басанцова Надежда | F13: ПА | G13: ООО "Фабрика счастья"
A14: 29 | B14: 2025 | C14: 3 | D14: 18 | E14: Басанцова Надежда | F14: Картирование | G14: АО "ЛСР-Краны-Северо-Запад"
A15: 30 | B15: 2025 | C15: 3 | D15: 18 | E15: Басанцова Надежда | F15: ПА | G15: АО "ЛСР-Краны-Северо-Запад"
A16: 31 | B16: 2025 | C16: 3 | D16: 19 | E16: Басанцова Надежда | F16: Картирование | G16: ООО "Фабрика счастья"
A17: 32 | B17: 2025 | C17: 3 | D17: 19 | E17: Басанцова Надежда | F17: ПА | G17: ООО "Фабрика счастья"
A18: 34 | B18: 2025 | C18: 3 | D18: 27 | E18: Басанцова Надежда | F18: ОБП | G18: ООО "Красивый город"
A19: 38 | B19: 2025 | C19: 4 | D19: 1 | E19: Басанцова Надежда | F19: ОБП | G19: ООО "ДизайнИнвест"
A20: 43 | B20: 2025 | C20: 4 | D20: 2 | E20: Басанцова Надежда | F20: РПУ | G20: ООО "ДизайнИнвест"
A21: 44 | B21: 2025 | C21: 4 | D21: 2 | E21: Басанцова Надежда | F21: 5С | G21: ООО "ДизайнИнвест"
A22: 49 | B22: 2025 | C22: 4 | D22: 4 | E22: Басанцова Надежда | F22: Картирование | G22: ООО "ДизайнИнвест"
... A89: 405 | B89: 2025 | C89: 12 | D89: 10 | E89: Басанцова Надежда | F89: Мет.реш.проблем | G89: АО "НИИВС "Спектр"
A90: 407 | B90: 2025 | C90: 12 | D90: 3 | E90: Басанцова Надежда | F90: СР | G90: ООО "Макро СП" | H90: 90
A91: 54 | B91: 2025 | C91: 4 | D91: 9 | E91: Васильева Светлана | F91: ПА | G91: ООО "ГСП Переработка"
A92: 57 | B92: 2025 | C92: 4 | D92: 11 | E92: Васильева Светлана | F92: МРП | G92: ООО "ГСП Переработка"
A93: 85 | B93: 2025 | C93: 5 | D93: 13 | E93: Васильева Светлана | F93: СР | G93: ООО "ГСП Переработка"
A94: 87 | B94: 2025 | C94: 5 | D94: 15 | E94: Васильева Светлана | F94: ОБП | G94: АО "Концерн "МПО-Гидроприбор"
A95: 91 | B95: 2025 | C95: 5 | D95: 20 | E95: Васильева Светлана | F95: РПУ | G95: АО "Концерн "МПО-Гидроприбор"
A96: 92 | B96: 2025 | C96: 5 | D96: 20 | E96: Васильева Светлана | F96: 5С | G96: АО "Концерн "МПО-Гидроприбор"
A97: 97 | B97: 2025 | C97: 5 | D97: 23 | E97: Васильева Светлана | F97: МРП | G97: ООО "Фабрика счастья"
A98: 101 | B98: 2025 | C98: 5 | D98: 22 | E98: Васильева Светлана | F98: Картирование | G98: АО "Концерн "МПО-Гидроприбор"
A99: 102 | B99: 2025 | C99: 5 | D99: 22 | E99: Васильева Светлана | F99: ПА | G99: АО "Концерн "МПО-Гидроприбор"
A100: 142 | B100: 2025 | C100: 6 | D100: 26 | E100: Васильева Светлана | F100: Мет.реш.проблем | G100: ООО "Стройкрафт"
A101: 143 | B101: 2025 | C101: 6 | D101: 18 | E101: Васильева Светлана | F101: ОБП | G101: ООО "ГСП-Технологии"
A102: 144 | B102: 2025 | C102: 6 | D102: 20 | E102: Васильева Светлана | F102: РПУ | G102: ООО "ГСП-Технологии"
... A142: 387 | B142: 2025 | C142: 11 | D142: 6 | E142: Васильева Светлана | F142: Мет.реш.проблем | G142: ООО Промстройрегион"
A143: 388 | B143: 2025 | C143: 11 | D143: 12 | E143: Васильева Светлана | F143: СР | G143: ООО Промстройрегион" | H143: 53
A144: 219 | B144: 2025 | C144: 8 | D144: 7 | E144: Лёвкина Наталья | F144: РПУ | G144: АО "НЭО"
A145: 220 | B145: 2025 | C145: 8 | D145: 7 | E145: Лёвкина Наталья | F145: 5С | G145: АО "НЭО"
...

Sheet январь
A1: День | B1: ФИО тренера | C1: Тренинг | D1: Предприятие | E1: NPS
A2: 15 | B2: Басанцова Надежда | C2: РПУ | D2: ООО "ПО Лузар" | E2: 0.78
A3: 15 | B3: Басанцова Надежда | C3: 5С | D3: ООО "ПО Лузар" | E3: 0.88
A4: 20 | B4: Басанцова Надежда | C4: Картирование | D4: ООО "ПО Лузар" | E4: 0.9
A5: 20 | B5: Басанцова Надежда | C5: ПА | D5: ООО "ПО Лузар" | E5: 0.82
A6: 31 | B6: Басанцова Надежда | C6: ОБП | D6: ООО "Старк-СПб" | E6: 1
A7: 17 | B7: Туранов Кирилл | C7: ОБП | D7: ООО "Прогресс-СП" | E7: 1
A8: 22 | B8: Туранов Кирилл | C8: РПУ | D8: ООО "Прогресс-СП" | E8: 1
A9: 22 | B9: Туранов Кирилл | C9: 5С | D9: ООО "Прогресс-СП" | E9: 1
A10: 29 | B10: Туранов Кирилл | C10: Картирование | D10: ООО "Прогресс-СП" | E10: 1
A11: 29 | B11: Туранов Кирилл | C11: ПА | D11: ООО "Прогресс-СП" | E11: 1
A12: 13 | B12: Туранов Кирилл | C12: ОБП | D12: ООО "ПО Лузар" | E12: 0.78

Sheet февраль
A1: День | B1: ФИО тренера | C1: Тренинг | D1: Предприятие | E1: NPS
A2: 5 | B2: Басанцова Надежда | C2: РПУ | D2: ООО "Старк-СПб" | E2: 0.78
A3: 5 | B3: Басанцова Надежда | C3: 5С | D3: ООО "Старк-СПб" | E3: 1
A4: 12 | B4: Басанцова Надежда | C4: Картирование | D4: ООО "Старк-СПб" | E4: 0.91
A5: 12 | B5: Басанцова Надежда | C5: ПА | D5: ООО "Старк-СПб" | E5: 1
A6: 25 | B6: Басанцова Надежда | C6: ОБП | D6: АО "ЛСР-Краны-Северо-Запад" | E6: 0.86
A7: 14 | B7: Туранов Кирилл | C7: Картирование | D7: ООО "ГСП-Переработка" | E7: 1
A8: 20 | B8: Туранов Кирилл | C8: СР | D8: ООО "ПО Лузар" | E8: 0.8
A9: 24 | B9: Туранов Кирилл | C9: АО | D9: ООО "ПО Лузар" | E9: 0.9
A10: 24 | B10: Туранов Кирилл | C10: СМЕД | D10: ООО "ПО Лузар" | E10: 0.8
A11: 11 | B11: Уваров Константин | C11: ОБП | D11: ООО "ГСП-Переработка" | E11: 1
A12: 12 | B12: Уваров Константин | C12: РПУ | D12: ООО "ГСП-Переработка" | E12: 1
A13: 12 | B13: Уваров Константин | C13: 5С | D13: ООО "ГСП-Переработка" | E13: 0.88

Sheet март
A1: 2025 | B1: 3 | C1: 18 | D1: Басанцова Надежда | E1: Картирование | F1: АО "ЛСР-Краны-Северо-Запад" | G1: 0.83
A2: 2025 | B2: 3 | C2: 19 | D2: Басанцова Надежда | E2: Картирование | F2: ООО "Фабрика счастья" | G2: 0.83
A3: 2025 | B3: 3 | C3: 14 | D3: Басанцова Надежда | E3: ОБП | F3: ООО "Фабрика счастья" | G3: 1
A4: 2025 | B4: 3 | C4: 27 | D4: Басанцова Надежда | E4: ОБП | F4: ООО "Красивый город" | G4: 0.82
A5: 2025 | B5: 3 | C5: 17 | D5: Басанцова Надежда | E5: ПА | F5: ООО "Фабрика счастья" | G5: 1
A6: 2025 | B6: 3 | C6: 18 | D6: Басанцова Надежда | E6: ПА | F6: АО "ЛСР-Краны-Северо-Запад" | G6: 0.8
A7: 2025 | B7: 3 | C7: 19 | D7: Басанцова Надежда | E7: ПА | F7: ООО "Фабрика счастья" | G7: 0.73
A8: 2025 | B8: 3 | C8: 17 | D8: Басанцова Надежда | E8: РПУ | F8: ООО "Фабрика счастья" | G8: 0.88
A9: 2025 | B9: 3 | C9: 28 | D9: Туранов Кирилл | E9: СР | F9: ООО "Прогресс-СП" | G9: 1
A10: 2025 | B10: 3 | C10: 28 | D10: Хлебников Александр | E10: 5С | F10: ООО "Авентин Инжиниринг" | G10: 0.8
A11: 2025 | B11: 3 | C11: 21 | D11: Хлебников Александр | E11: ОБП | F11: ООО "Авентин Инжиниринг" | G11: 0.8
A12: 2025 | B12: 3 | C12: 28 | D12: Хлебников Александр | E12: РПУ | F12: ООО "Авентин Инжиниринг" | G12: 0.88
... A14: 2025 | B14: 3 | C14: 4 | D14: Хлебников Александр | E14: 5С | F14: АО "ЛСР-Краны-Северо-Запад" | G14: 1

Sheet апрель
A1: 2025 | B1: 4 | C1: 1 | D1: Басанцова Надежда | E1: ОБП | F1: ООО "ДизайнИнвест" | G1: 11 | H1: 11 | I1: 0 | J1: 9 | K1: =IFERROR(J1/H1-I1/H1,"") -> 0.81818182
A2: 2025 | B2: 4 | C2: 2 | D2: Басанцова Надежда | E2: 5С | F2: ООО "ДизайнИнвест" | G2: 7 | H2: 7 | I2: 0 | J2: 6 | K2: =IFERROR(J2/H2-I2/H2,"") -> 0.85714286
A3: 2025 | B3: 4 | C3: 8 | D3: Басанцова Надежда | E3: 5С | F3: ООО "Стройкрафт" | G3: 7 | H3: 7 | I3: 0 | J3: 6 | K3: =IFERROR(J3/H3-I3/H3,"") -> 0.85714286
A4: 2025 | B4: 4 | C4: 16 | D4: Туранов Кирилл | E4: 5С | F4: ООО "ГСП-7" | G4: 10 | H4: 10 | I4: 0 | J4: 7 | K4: =IFERROR(J4/H4-I4/H4,"") -> 0.7
A5: 2025 | B5: 4 | C5: 8 | D5: Уваров Константин | E5: 5С | F5: ООО "Новый профиль" | G5: 6 | H5: 5 | I5: 0 | J5: 3 | K5: =IFERROR(J5/H5-I5/H5,"") -> 0.6
A6: 2025 | B6: 4 | C6: 30 | D6: Уваров Константин | E6: 5С | F6: ООО "Океан" | G6: 6 | H6: 5 | I6: 0 | J6: 5 | K6: =IFERROR(J6/H6-I6/H6,"") -> 1
A7: 2025 | B7: 4 | C7: 1 | D7: Хлебников Александр | E7: 5С | F7: ООО "Красивый город" | G7: 12 | H7: 12 | I7: 0 | J7: 9 | K7: =IFERROR(J7/H7-I7/H7,"") -> 0.75
A8: 2025 | B8: 4 | C8: 9 | D8: Хлебников Александр | E8: 5С | F8: АО "НИИ "Нептун" | G8: 8 | H8: 8 | I8: 0 | J8: 8 | K8: =IFERROR(J8/H8-I8/H8,"") -> 1
A9: 2025 | B9: 4 | C9: 18 | D9: Хлебников Александр | E9: 5С | F9: ООО "Родвиг" | G9: 10 | H9: 10 | I9: 0 | J9: 9 | K9: =IFERROR(J9/H9-I9/H9,"") -> 0.9
A10: 2025 | B10: 4 | C10: 1 | D10: Туранов Кирилл | E10: АО | F10: ООО "Прогресс-СП" | G10: 3 | H10: 3 | I10: 0 | J10: 3 | K10: =IFERROR(J10/H10-I10/H10,"") -> 1
A11: 2025 | B11: 4 | C11: 4 | D11: Басанцова Надежда | E11: Картирование | F11: ООО "ДизайнИнвест" | G11: 10 | H11: 8 | I11: 0 | J11: 6 | K11: =IFERROR(J11/H11-I11/H11,"") -> 0.75
A12: 2025 | B12: 4 | C12: 2 | D12: Туранов Кирилл | E12: Картирование | F12: ООО "Красивый город" | G12: 9 | H12: 9 | I12: 0 | J12: 7 | K12: =IFERROR(J12/H12-I12/H12,"") -> 0.77777778
... A27: 2025 | B27: 4 | C27: 4 | D27: Басанцова Надежда | E27: ПА | F27: ООО "ДизайнИнвест" | G27: 10 | H27: 9 | I27: 0 | J27: 7 | K27: =IFERROR(J27/H27-I27/H27,"") -> 0.77777778
A28: 2025 | B28: 4 | C28: 9 | D28: Васильева Светлана | E28: ПА | F28: ООО "ГСП Переработка" | G28: 7 | H28: 4 | I28: 0 | J28: 4 | K28: 1
A29: 2025 | B29: 4 | C29: 2 | D29: Туранов Кирилл | E29: ПА | F29: ООО "Красивый город" | G29: 9 | H29: 9 | I29: 0 | J29: 7 | K29: =IFERROR(J29/H29-I29/H29,"") -> 0.77777778
A30: 2025 | B30: 4 | C30: 17 | D30: Туранов Кирилл | E30: ПА | F30: ООО "ГСП-7" | G30: 6 | H30: 6 | I30: 0 | J30: 6 | K30: =IFERROR(J30/H30-I30/H30,"") -> 1
A31: 2025 | B31: 4 | C31: 9 | D31: Уваров Константин | E31: ПА | F31: ООО "Океан" | G31: 5 | H31: 5 | I31: 0 | J31: 4 | K31: =IFERROR(J31/H31-I31/H31,"") -> 0.8
A32: 2025 | B32: 4 | C32: 11 | D32: Уваров Константин | E32: ПА | F32: ООО "Новый профиль" | G32: 6 | H32: 6 | I32: 0 | J32: 3 | K32: =IFERROR(J32/H32-I32/H32,"") -> 0.5
A33: 2025 | B33: 4 | C33: 29 | D33: Уваров Константин | E33: ПА | F33: ООО "Родвиг" | G33: 10 | H33: 6 | I33: 0 | J33: 3 | K33: =IFERROR(J33/H33-I33/H33,"") -> 0.5
A34: 2025 | B34: 4 | C34: 2 | D34: Хлебников Александр | E34: ПА | F34: ООО "Авентин Инжиниринг" | G34: 10 | H34: 8 | I34: 0 | J34: 6 | K34: =IFERROR(J34/H34-I34/H34,"") -> 0.75
A35: 2025 | B35: 4 | C35: 11 | D35: Хлебников Александр | E35: ПА | F35: ООО "Стройкрафт" | G35: 6 | H35: 6 | I35: 0 | J35: 5 | K35: =IFERROR(J35/H35-I35/H35,"") -> 0.83333333
A36: 2025 | B36: 4 | C36: 10 | D36: Хлебников Александр | E36: ПА | F36: АО "НИИ "Нептун" | G36: 9 | H36: 9 | I36: 0 | J36: 9 | K36: =IFERROR(J36/H36-I36/H36,"") -> 1
A37: 2025 | B37: 4 | C37: 2 | D37: Басанцова Надежда | E37: РПУ | F37: ООО "ДизайнИнвест" | G37: 7 | H37: 7 | I37: 0 | J37: 5 | K37: =IFERROR(J37/H37-I37/H37,"") -> 0.71428571
A38: 2025 | B38: 4 | C38: 8 | D38: Басанцова Надежда | E38: РПУ | F38: ООО "Стройкрафт" | G38: 7 | H38: 7 | I38: 0 | J38: 6 | K38: =IFERROR(J38/H38-I38/H38,"") -> 0.85714286
A39: 2025 | B39: 4 | C39: 16 | D39: Туранов Кирилл | E39: РПУ | F39: ООО "ГСП-7" | G39: 10 | H39: 10 | I39: 0 | J39: 7 | K39: =IFERROR(J39/H39-I39/H39,"") -> 0.7
A40: 2025 | B40: 4 | C40: 9 | D40: Уваров Константин | E40: РПУ | F40: ООО "Океан" | G40: 5 | H40: 5 | I40: 0 | J40: 4 | K40: =IFERROR(J40/H40-I40/H40,"") -> 0.8
... A46: 2025 | B46: 4 | C46: 30 | D46: Басанцова Надежда | E46: СР | F46: ООО "Фабрика счастья" | G46: 13 | H46: 13 | I46: 0 | J46: 13 | K46: =IFERROR(J46/H46-I46/H46,"") -> 1

Sheet май
A1: 2025 | B1: 5 | C1: 7 | D1: Уваров Константин | E1: Картирование | F1: ООО "Океан" | G1: 4 | H1: 4 | I1: 0 | J1: 4 | K1: =IFERROR(J1/H1-I1/H1,"") -> 1
A2: 2025 | B2: 5 | C2: 13 | D2: Басанцова Надежда | E2: ОБП | F2: ООО "Арайд" | G2: 11 | H2: 10 | I2: 0 | J2: 8 | K2: =IFERROR(J2/H2-I2/H2,"") -> 0.8
A3: 2025 | B3: 5 | C3: 13 | D3: Васильева Светлана | E3: СР | F3: ООО "ГСП Переработка" | G3: 7 | H3: 5 | I3: 0 | J3: 5 | K3: =IFERROR(J3/H3-I3/H3,"") -> 1
A4: 2025 | B4: 5 | C4: 15 | D4: Васильева Светлана | E4: ОБП | F4: АО "Концерн "МПО-Гидроприбор" | G4: 16 | H4: 12 | I4: 0 | J4: 9 | K4: =IFERROR(J4/H4-I4/H4,"") -> 0.75
A5: 2025 | B5: 5 | C5: 15 | D5: Хлебников Александр | E5: СР | F5: АО "НИИ "Нептун" | G5: 6 | H5: 6 | I5: 0 | J5: 5 | K5: =IFERROR(J5/H5-I5/H5,"") -> 0.83333333
A6: 2025 | B6: 5 | C6: 19 | D6: Басанцова Надежда | E6: 5С | F6: ООО "Арайд" | G6: 12 | H6: 12 | I6: 0 | J6: 9 | K6: =IFERROR(J6/H6-I6/H6,"") -> 0.75
A7: 2025 | B7: 5 | C7: 19 | D7: Басанцова Надежда | E7: РПУ | F7: ООО "Арайд" | G7: 12 | H7: 12 | I7: 0 | J7: 10 | K7: =IFERROR(J7/H7-I7/H7,"") -> 0.83333333
A8: 2025 | B8: 5 | C8: 20 | D8: Васильева Светлана | E8: 5С | F8: АО "Концерн "МПО-Гидроприбор" | G8: 14 | H8: 8 | I8: 0 | J8: 6 | K8: =IFERROR(J8/H8-I8/H8,"") -> 0.75
A9: 2025 | B9: 5 | C9: 20 | D9: Чуприков Станислав | E9: ОБП | F9: ООО "ГАЗСТРОЙТЕХ" | G9: 6 | H9: 6 | I9: 0 | J9: 4 | K9: =IFERROR(J9/H9-I9/H9,"") -> 0.66666667
A10: 2025 | B10: 5 | C10: 20 | D10: Васильева Светлана | E10: РПУ | F10: АО "Концерн "МПО-Гидроприбор" | G10: 15 | H10: 11 | I10: 0 | J10: 8 | K10: =IFERROR(J10/H10-I10/H10,"") -> 0.72727273
A11: 2025 | B11: 5 | C11: 20 | D11: Туранов Кирилл | E11: СР | F11: ООО "Новый профиль" | G11: 6 | H11: 5 | I11: 0 | J11: 4 | K11: =IFERROR(J11/H11-I11/H11,"") -> 0.8
A12: 2025 | B12: 5 | C12: 22 | D12: Васильева Светлана | E12: Картирование | F12: АО "Концерн "МПО-Гидроприбор" | G12: 13 | H12: 13 | I12: 0 | J12: 11 | K12: =IFERROR(J12/H12-I12/H12,"") -> 0.84615385
... A16: 2025 | B16: 5 | C16: 22 | D16: Чуприков Станислав | E16: ПА | F16: ООО "ГАЗСТРОЙТЕХ" | G16: 7 | H16: 7 | I16: 0 | J16: 5 | K16: =IFERROR(J16/H16-I16/H16,"") -> 0.71428571
A17: 2025 | B17: 5 | C17: 22 | D17: Чуприков Станислав | E17: РПУ | F17: ООО "ГАЗСТРОЙТЕХ" | G17: 7 | H17: 7 | I17: 0 | J17: 5 | K17: 0.75
A18: 2025 | B18: 5 | C18: 23 | D18: Васильева Светлана | E18: МРП | F18: ООО "Фабрика счастья" | G18: 10 | H18: 9 | I18: 0 | J18: 8 | K18: =IFERROR(J18/H18-I18/H18,"") -> 0.88888889
A19: 2025 | B19: 5 | C19: 23 | D19: Басанцова Надежда | E19: ОБП | F19: ООО "Техмастер" | G19: 10 | H19: 10 | I19: 0 | J19: 7 | K19: =IFERROR(J19/H19-I19/H19,"") -> 0.7
A20: 2025 | B20: 5 | C20: 26 | D20: Туранов Кирилл | E20: ОБП | F20: ООО "ЗСК "КВАЛИТЕТ" | G20: 12 | H20: 11 | I20: 0 | J20: 8 | K20: =IFERROR(J20/H20-I20/H20,"") -> 0.72727273
A21: 2025 | B21: 5 | C21: 27 | D21: Чуприков Станислав | E21: 5С | F21: ООО "ГАЗСТРОЙТЕХ" | G21: 7 | H21: 8 | I21: 0 | J21: 7 | K21: =IFERROR(J21/H21-I21/H21,"") -> 0.875
A22: 2025 | B22: 5 | C22: 27 | D22: Чуприков Станислав | E22: Картирование | F22: ООО "ГАЗСТРОЙТЕХ" | G22: 7 | H22: 8 | I22: 0 | J22: 6 | K22: =IFERROR(J22/H22-I22/H22,"") -> 0.75
A23: 2025 | B23: 5 | C23: 27 | D23: Туранов Кирилл | E23: ОЕЕ | F23: ООО "Новый профиль" | G23: 3 | H23: 3 | I23: 0 | J23: 3 | K23: =IFERROR(J23/H23-I23/H23,"") -> 1
A24: 2025 | B24: 5 | C24: 27 | D24: Туранов Кирилл | E24: СМЕД | F24: ООО "Новый профиль" | G24: 3 | H24: 3 | I24: 0 | J24: 3 | K24: =IFERROR(J24/H24-I24/H24,"") -> 1
A25: 2025 | B25: 5 | C25: 27 | D25: Басанцова Надежда | E25: СР | F25: ООО "Красивый город" | G25: 10 | H25: 10 | I25: 0 | J25: 8 | K25: =IFERROR(J25/H25-I25/H25,"") -> 0.8
A26: 2025 | B26: 5 | C26: 30 | D26: Уваров Константин | E26: 5С | F26: ООО "Техмастер" | G26: 11 | K26: =IFERROR(J26/H26-I26/H26,"")
A27: 2025 | B27: 5 | C27: 30 | D27: Уваров Константин | E27: РПУ | F27: ООО "Техмастер" | G27: 11 | K27: =IFERROR(J27/H27-I27/H27,"")
A28: 2025 | B28: 5 | C28: 30 | D28: Басанцова Надежда | E28: СР | F28: ООО "Стройкрафт" | G28: 3 | H28: 3 | I28: 0 | J28: 3 | K28: =IFERROR(J28/H28-I28/H28,"") -> 1

Sheet июнь
A1: 6 | B1: 2 | C1: Туранов Кирилл | D1: РПУ | E1: ООО "ЗСК "КВАЛИТЕТ" | F1: 13 | G1: 10 | H1: 0 | I1: 7 | J1: =IFERROR(I1/G1-H1/G1,"") -> 0.7
A2: 6 | B2: 20 | C2: Васильева Светлана | D2: 5С | E2: ООО "ГСП-Технологии" | F2: 4 | G2: 4 | H2: 0 | I2: 3 | J2: =IFERROR(I2/G2-H2/G2,"") -> 0.75
A3: 6 | B3: 2 | C3: Туранов Кирилл | D3: 5С | E3: ООО "ЗСК "КВАЛИТЕТ" | F3: 13 | G3: 11 | H3: 0 | I3: 8 | J3: =IFERROR(I3/G3-H3/G3,"") -> 0.72727273
A4: 6 | B4: 19 | C4: Туранов Кирилл | D4: 5С | E4: ООО "КВС" | F4: 16 | G4: 12 | H4: 0 | I4: 9 | J4: =IFERROR(I4/G4-H4/G4,"") -> 0.75
A5: 6 | B5: 3 | C5: Уваров Константин | D5: 5С | E5: ООО "Балтинвестстрой" | F5: 10 | G5: 4 | H5: 0 | I5: 4 | J5: =IFERROR(I5/G5-H5/G5,"") -> 1
A6: 6 | B6: 4 | C6: Хлебников Александр | D6: 5С | E6: ООО "КВС-строй" | F6: 8 | G6: 7 | H6: 0 | I6: 7 | J6: =IFERROR(I6/G6-H6/G6,"") -> 1
A7: 6 | B7: 6 | C7: Басанцова Надежда | D7: АО | E7: ООО "Красивый город" | F7: 8 | G7: 7 | H7: 0 | I7: 6 | J7: =IFERROR(I7/G7-H7/G7,"") -> 0.85714286
A8: 6 | B8: 9 | C8: Уваров Константин | D8: АО | E8: ООО "Родвиг" | F8: 6 | G8: 4 | H8: 0 | I8: 3 | J8: =IFERROR(I8/G8-H8/G8,"") -> 0.75
A9: 6 | B9: 25 | C9: Басанцова Надежда | D9: Картирование | E9: ООО "ГСП-Технологии" | F9: 4 | G9: 4 | H9: 0 | I9: 3 | J9: =IFERROR(I9/G9-H9/G9,"") -> 0.75
A10: 6 | B10: 5 | C10: Туранов Кирилл | D10: Картирование | E10: ООО "ЗСК "КВАЛИТЕТ" | F10: 13 | G10: 10 | H10: 0 | I10: 8 | J10: =IFERROR(I10/G10-H10/G10,"") -> 0.8
A11: 6 | B11: 24 | C11: Туранов Кирилл | D11: Картирование | E11: ООО "КВС" | F11: 16 | G11: 15 | H11: 0 | I11: 11 | J11: =IFERROR(I11/G11-H11/G11,"") -> 0.73333333
A12: 6 | B12: 6 | C12: Уваров Константин | D12: Картирование | E12: ООО "Техмастер" | F12: 9 | G12: 7 | H12: 0 | I12: 6 | J12: =IFERROR(I12/G12-H12/G12,"") -> 0.85714286
... A31: 6 | B31: 3 | C31: Уваров Константин | D31: РПУ | E31: ООО "Балтинвестстрой" | F31: 11 | G31: 4 | H31: 0 | I31: 3 | J31: =IFERROR(I31/G31-H31/G31,"") -> 0.75
A32: 6 | B32: 4 | C32: Хлебников Александр | D32: РПУ | E32: ООО "КВС-строй" | F32: 8 | G32: 7 | H32: 0 | I32: 7 | J32: 1
A33: 6 | B33: 4 | C33: Басанцова Надежда | D33: СР | E33: ООО "ДизайнИнвест" | F33: 8 | G33: 8 | H33: 0 | I33: 6 | J33: =IFERROR(I33/G33-H33/G33,"") -> 0.75
A34: 6 | B34: 16 | C34: Васильева Светлана | D34: СР | E34: ООО "Старк-СПб" | F34: 6 | G34: 6 | H34: 0 | I34: 5 | J34: =IFERROR(I34/G34-H34/G34,"") -> 0.83333333
A35: 6 | B35: 9 | C35: Уваров Константин | D35: СР | E35: ООО "Родвиг" | F35: 6 | G35: 4 | H35: 0 | I35: 4 | J35: =IFERROR(I35/G35-H35/G35,"") -> 1
A36: 6 | B36: 26 | C36: Хлебников Александр | D36: СР | E36: ООО "Авентин Инжиниринг" | F36: 7 | G36: 7 | H36: 0 | I36: 7 | J36: =IFERROR(I36/G36-H36/G36,"") -> 1

Sheet июль
A1: 7 | B1: 1 | C1: Уваров Константин | D1: ОБП | E1: ООО "Артекс" | F1: 11 | G1: 7 | H1: 1 | I1: 5 | J1: 0.63
A2: 7 | B2: 18 | C2: Басанцова Надежда | D2: 5С | E2: ООО "Светосервис-СПб" | F2: 6 | G2: 6 | H2: 0 | I2: 5 | J2: =IFERROR(I2/G2-H2/G2,"") -> 0.83333333
A3: 7 | B3: 29 | C3: Басанцова Надежда | D3: 5С | E3: ООО "ЕТС Корда" | F3: 13 | G3: 12 | H3: 1 | I3: 11 | J3: =IFERROR(I3/G3-H3/G3,"") -> 0.83333333
A4: 7 | B4: 30 | C4: Басанцова Надежда | D4: SMED | E4: ООО "ГСП-Технологии" | F4: 8 | G4: 8 | H4: 0 | I4: 8 | J4: =IFERROR(I4/G4-H4/G4,"") -> 1
A5: 7 | B5: 16 | C5: Басанцова Надежда | D5: Картирование | E5: ООО "Светосервис-СПб" | F5: 8 | G5: 8 | H5: 0 | I5: 6 | J5: =IFERROR(I5/G5-H5/G5,"") -> 0.75
A6: 7 | B6: 1 | C6: Басанцова Надежда | D6: ОБП | E6: АО "Красный дельфин" | F6: 12 | G6: 12 | H6: 0 | I6: 11 | J6: =IFERROR(I6/G6-H6/G6,"") -> 0.91666667
A7: 7 | B7: 8 | C7: Басанцова Надежда | D7: ОБП | E7: ООО "Геоскан" | F7: 13 | G7: 13 | H7: 0 | I7: 10 | J7: =IFERROR(I7/G7-H7/G7,"") -> 0.76923077
A8: 7 | B8: 16 | C8: Басанцова Надежда | D8: ПА | E8: ООО "Светосервис-СПб" | F8: 8 | G8: 8 | H8: 0 | I8: 6 | J8: =IFERROR(I8/G8-H8/G8,"") -> 0.75
A9: 7 | B9: 18 | C9: Басанцова Надежда | D9: РПУ | E9: ООО "Светосервис-СПб" | F9: 6 | G9: 6 | H9: 0 | I9: 5 | J9: =IFERROR(I9/G9-H9/G9,"") -> 0.83333333
A10: 7 | B10: 29 | C10: Басанцова Надежда | D10: РПУ | E10: ООО "ЕТС Корда" | F10: 13 | G10: 13 | H10: 0 | I10: 11 | J10: =IFERROR(I10/G10-H10/G10,"") -> 0.84615385
A11: 7 | B11: 17 | C11: Басанцова Надежда | D11: СР | E11: ООО "ГСП-Технологии" | F11: 7 | G11: 7 | H11: 0 | I11: 6 | J11: =IFERROR(I11/G11-H11/G11,"") -> 0.85714286
A12: 7 | B12: 3 | C12: Васильева Светлана | D12: 5С | E12: ООО "Невастройторг" | F12: 10 | G12: 10 | H12: 0 | I12: 8 | J12: =IFERROR(I12/G12-H12/G12,"") -> 0.8
A13: 7 | B13: 4 | C13: Васильева Светлана | D13: Картирование | E13: АО "Красный дельфин" | F13: 13 | G13: 10 | H13: 0 | I13: 8 | J13: =IFERROR(I13/G13-H13/G13,"") -> 0.8
... A21: 7 | B21: 10 | C21: Туранов Кирилл | D21: Мет.реш.проблем | E21: ООО "ГСП-7" | F21: 3 | G21: 3 | H21: 0 | I21: 3 | J21: =IFERROR(I21/G21-H21/G21,"") -> 1
A22: 7 | B22: 1 | C22: Туранов Кирилл | D22: ОБП | E22: ООО "Невастройторг" | F22: 12 | G22: 12 | H22: 0 | I22: 0 | J22: 1
A23: 7 | B23: 11 | C23: Туранов Кирилл | D23: ОБП | E23: ООО "Светосервис-СПб" | F23: 8 | G23: 8 | H23: 0 | I23: 6 | J23: =IFERROR(I23/G23-H23/G23,"") -> 0.75
A24: 7 | B24: 23 | C24: Туранов Кирилл | D24: ОБП | E24: ООО "ЕТС Корда" | F24: 13 | G24: 11 | H24: 0 | I24: 8 | J24: =IFERROR(I24/G24-H24/G24,"") -> 0.72727273
A25: 7 | B25: 22 | C25: Туранов Кирилл | D25: ОЕЕ | E25: ООО "Невастройторг" | F25: 6 | G25: 6 | H25: 0 | I25: 5 | J25: =IFERROR(I25/G25-H25/G25,"") -> 0.83333333
A26: 7 | B26: 9 | C26: Туранов Кирилл | D26: СР | E26: ООО "ГСП-7" | F26: 3 | G26: 3 | H26: 0 | I26: 3 | J26: =IFERROR(I26/G26-H26/G26,"") -> 1
A27: 7 | B27: 16 | C27: Туранов Кирилл | D27: СР | E27: ООО "ЗСК "КВАЛИТЕТ" | F27: 9 | G27: 9 | H27: 0 | I27: 9 | J27: =IFERROR(I27/G27-H27/G27,"") -> 1
A28: 7 | B28: 2 | C28: Уваров Константин | D28: 5С | E28: АО "Красный дельфин" | F28: 16 | J28: =IFERROR(I28/G28-H28/G28,"")
A29: 7 | B29: 3 | C29: Уваров Константин | D29: 5С | E29: ООО "Артекс" | F29: 7 | G29: 7 | H29: 0 | I29: 6 | J29: =IFERROR(I29/G29-H29/G29,"") -> 0.85714286
A30: 7 | B30: 10 | C30: Уваров Константин | D30: 5С | E30: ООО "ВПК-Полимеры" | F30: 11 | G30: 5 | H30: 0 | I30: 5 | J30: =IFERROR(I30/G30-H30/G30,"") -> 1
A31: 7 | B31: 17 | C31: Уваров Константин | D31: SMED | E31: АО "Концерн "МПО-Гидроприбор" | F31: 5 | G31: 5 | H31: 0 | I31: 4 | J31: =IFERROR(I31/G31-H31/G31,"") -> 0.8
A32: 7 | B32: 17 | C32: Уваров Константин | D32: АО | E32: АО "Концерн "МПО-Гидроприбор" | F32: 6 | G32: 5 | H32: 0 | I32: 5 | J32: =IFERROR(I32/G32-H32/G32,"") -> 1
A33: 7 | B33: 8 | C33: Уваров Константин | D33: Картирование | E33: ООО "ВПК-Полимеры" | F33: 6 | G33: 5 | H33: 0 | I33: 4 | J33: =IFERROR(I33/G33-H33/G33,"") -> 0.8
A34: 7 | B34: 18 | C34: Уваров Константин | D34: ОЕЕ | E34: ООО "Техмастер" | F34: 8 | G34: 5 | H34: 0 | I34: 5 | J34: =IFERROR(I34/G34-H34/G34,"") -> 1
A35: 7 | B35: 23 | C35: Уваров Константин | D35: ОЕЕ | E35: ООО "Океан" | F35: 4 | G35: 4 | H35: 0 | I35: 4 | J35: =IFERROR(I35/G35-H35/G35,"") -> 1
A36: 7 | B36: 8 | C36: Уваров Константин | D36: ПА | E36: ООО "ВПК-Полимеры" | F36: 6 | G36: 5 | H36: 0 | I36: 5 | J36: =IFERROR(I36/G36-H36/G36,"") -> 1
A37: 7 | B37: 2 | C37: Уваров Константин | D37: РПУ | E37: АО "Красный дельфин" | F37: 16 | J37: =IFERROR(I37/G37-H37/G37,"")
A38: 7 | B38: 3 | C38: Уваров Константин | D38: РПУ | E38: ООО "Артекс" | F38: 11 | G38: 7 | H38: 0 | I38: 6 | J38: =IFERROR(I38/G38-H38/G38,"") -> 0.85714286
A39: 7 | B39: 10 | C39: Уваров Константин | D39: РПУ | E39: ООО "ВПК-Полимеры" | F39: 11 | G39: 5 | H39: 0 | I39: 4 | J39: =IFERROR(I39/G39-H39/G39,"") -> 0.8
A40: 7 | B40: 18 | C40: Уваров Константин | D40: СР | E40: ООО "Техмастер" | F40: 8 | G40: 6 | H40: 0 | I40: 5 | J40: =IFERROR(I40/G40-H40/G40,"") -> 0.83333333
A41: 7 | B41: 23 | C41: Уваров Константин | D41: СР | E41: ООО "Океан" | F41: 4 | G41: 4 | H41: 0 | I41: 3 | J41: =IFERROR(I41/G41-H41/G41,"") -> 0.75
A42: 7 | B42: 9 | C42: Хлебников Александр | D42: 5С | E42: ООО "Геоскан" | F42: 13 | G42: 13 | H42: 0 | I42: 12 | J42: =IFERROR(I42/G42-H42/G42,"") -> 0.92307692
A43: 7 | B43: 24 | C43: Хлебников Александр | D43: SMED | E43: ООО "Арайд" | F43: 8 | G43: 7 | H43: 1 | I43: 6 | J43: =IFERROR(I43/G43-H43/G43,"") -> 0.71428571
A44: 7 | B44: 30 | C44: Хлебников Александр | D44: Картирование | E44: ООО "ЕТС Корда" | F44: 13 | G44: 13 | H44: 0 | I44: 13 | J44: =IFERROR(I44/G44-H44/G44,"") -> 1
A45: 7 | B45: 2 | C45: Хлебников Александр | D45: Мет.реш.проблем | E45: ООО "Дизайнинвест" | F45: 8 | G45: 8 | H45: 0 | I45: 7 | J45: =IFERROR(I45/G45-H45/G45,"") -> 0.875
A46: 7 | B46: 3 | C46: Хлебников Александр | D46: Мет.реш.проблем | E46: ООО "Авентин Инжиниринг" | F46: 6 | G46: 5 | H46: 0 | I46: 4 | J46: =IFERROR(I46/G46-H46/G46,"") -> 0.8
A47: 7 | B47: 1 | C47: Хлебников Александр | D47: Мет.реш.проблем | E47: АО "ЛСР-Краны-Северо-Запад" | F47: 7 | G47: 7 | H47: 0 | I47: 7 | J47: =IFERROR(I47/G47-H47/G47,"") -> 1
...

Sheet август
A1: 8 | B1: 1 | C1: Басанцова Надежда | D1: ОБП | E1: ООО "СК Гидрокор" | F1: 11 | G1: 11 | H1: 1 | I1: 10 | J1: =IFERROR(I1/G1-H1/G1,"") -> 0.81818182
A2: 8 | B2: 5 | C2: Басанцова Надежда | D2: 5С | E2: ООО "СК Гидрокор" | F2: 13 | G2: 11 | H2: 0 | I2: 9 | J2: =IFERROR(I2/G2-H2/G2,"") -> 0.81818182
A3: 8 | B3: 26 | C3: Басанцова Надежда | D3: 5С | E3: ООО "ГК Миларин" | F3: 12 | G3: 10 | H3: 0 | I3: 10 | J3: =IFERROR(I3/G3-H3/G3,"") -> 1
A4: 8 | B4: 13 | C4: Басанцова Надежда | D4: Картирование | E4: ООО "СК Гидрокор" | F4: 12 | G4: 10 | H4: 0 | I4: 9 | J4: =IFERROR(I4/G4-H4/G4,"") -> 0.9
A5: 8 | B5: 19 | C5: Басанцова Надежда | D5: ОБП | E5: ООО "ГК Миларин" | F5: 13 | G5: 13 | H5: 0 | I5: 10 | J5: =IFERROR(I5/G5-H5/G5,"") -> 0.76923077
A6: 8 | B6: 27 | C6: Басанцова Надежда | D6: ОБП | E6: ООО "Миларин" | F6: 11 | G6: 10 | H6: 0 | I6: 8 | J6: =IFERROR(I6/G6-H6/G6,"") -> 0.8
A7: 8 | B7: 13 | C7: Басанцова Надежда | D7: ПА | E7: ООО "СК Гидрокор" | F7: 12 | G7: 10 | H7: 0 | I7: 8 | J7: =IFERROR(I7/G7-H7/G7,"") -> 0.8
A8: 8 | B8: 5 | C8: Басанцова Надежда | D8: РПУ | E8: ООО "СК Гидрокор" | F8: 13 | G8: 11 | H8: 0 | I8: 9 | J8: =IFERROR(I8/G8-H8/G8,"") -> 0.81818182
A9: 8 | B9: 26 | C9: Басанцова Надежда | D9: РПУ | E9: ООО "ГК Миларин" | F9: 12 | G9: 10 | H9: 0 | I9: 8 | J9: =IFERROR(I9/G9-H9/G9,"") -> 0.8
A10: 8 | B10: 14 | C10: Басанцова Надежда | D10: СР | E10: ООО "Геоскан" | F10: 7 | G10: 7 | H10: 0 | I10: 6 | J10: =IFERROR(I10/G10-H10/G10,"") -> 0.85714286
A11: 8 | B11: 4 | C11: Васильева Светлана | D11: 5С | E11: АО "Диаконт" | F11: 10 | G11: 7 | H11: 0 | I11: 5 | J11: =IFERROR(I11/G11-H11/G11,"") -> 0.71428571
A12: 8 | B12: 5 | C12: Васильева Светлана | D12: Картирование | E12: АО "Диаконт" | F12: 10 | G12: 10 | H12: 0 | I12: 8 | J12: =IFERROR(I12/G12-H12/G12,"") -> 0.8
... A50: 8 | B50: 19 | C50: Чуприков Станислав | D50: РПУ | E50: ООО "Интилед" | F50: 14 | G50: 13 | H50: 0 | I50: 11 | J50: =IFERROR(I50/G50-H50/G50,"") -> 0.84615385

Sheet сентябрь
A1: 9 | B1: 2 | C1: Басанцова Надежда | D1: ОБП | E1: ООО "ТД Калкулейт" | F1: 15 | G1: 12 | H1: 0 | I1: 10 | J1: =IFERROR(I1/G1-H1/G1,"") -> 0.83333333
A2: 9 | B2: 5 | C2: Басанцова Надежда | D2: 5С | E2: ООО "НЛС Силикон" | F2: 10 | G2: 9 | H2: 0 | I2: 7 | J2: =IFERROR(I2/G2-H2/G2,"") -> 0.77777778
A3: 9 | B3: 23 | C3: Басанцова Надежда | D3: 5С | E3: ООО "Корпорация Ди энд Ди" | F3: 5 | G3: 5 | H3: 0 | I3: 5 | J3: =IFERROR(I3/G3-H3/G3,"") -> 1
A4: 9 | B4: 4 | C4: Басанцова Надежда | D4: Картирование | E4: ООО "ГК Миларин" | F4: 11 | G4: 10 | H4: 1 | I4: 9 | J4: =IFERROR(I4/G4-H4/G4,"") -> 0.8
A5: 9 | B5: 11 | C5: Басанцова Надежда | D5: Картирование | E5: ООО "СЦ Телрос" | F5: 6 | G5: 6 | H5: 0 | I5: 5 | J5: =IFERROR(I5/G5-H5/G5,"") -> 0.83333333
A6: 9 | B6: 8 | C6: Басанцова Надежда | D6: ОБП | E6: ООО "Макро СП" | F6: 12 | G6: 12 | H6: 0 | I6: 9 | J6: =IFERROR(I6/G6-H6/G6,"") -> 0.75
A7: 9 | B7: 10 | C7: Басанцова Надежда | D7: ОБП | E7: ООО "Коннектор Системс" | F7: 9 | G7: 9 | H7: 0 | I7: 8 | J7: =IFERROR(I7/G7-H7/G7,"") -> 0.88888889
A8: 9 | B8: 4 | C8: Басанцова Надежда | D8: ПА | E8: ООО "ГК Миларин" | F8: 11 | G8: 10 | H8: 0 | I8: 9 | J8: =IFERROR(I8/G8-H8/G8,"") -> 0.9
A9: 9 | B9: 11 | C9: Басанцова Надежда | D9: ПА | E9: ООО "СЦ Телрос" | F9: 6 | G9: 6 | H9: 0 | I9: 5 | J9: =IFERROR(I9/G9-H9/G9,"") -> 0.83333333
A10: 9 | B10: 5 | C10: Басанцова Надежда | D10: РПУ | E10: ООО "НЛС Силикон" | F10: 10 | G10: 10 | H10: 0 | I10: 7 | J10: =IFERROR(I10/G10-H10/G10,"") -> 0.7
A11: 9 | B11: 23 | C11: Басанцова Надежда | D11: РПУ | E11: ООО "Корпорация Ди энд Ди" | F11: 5 | G11: 5 | H11: 0 | I11: 5 | J11: =IFERROR(I11/G11-H11/G11,"") -> 1
A12: 9 | B12: 24 | C12: Басанцова Надежда | D12: СР | E12: АО "Красный дельфин" | F12: 9 | G12: 9 | H12: 0 | I12: 7 | J12: =IFERROR(I12/G12-H12/G12,"") -> 0.77777778
... A73: 9 | B73: 22 | C73: Чуприков Станислав | D73: РПУ | E73: ООО "НПЦ "Авиационные системы" | F73: 9 | G73: 9 | H73: 0 | I73: 7 | J73: =IFERROR(I73/G73-H73/G73,"") -> 0.77777778

Sheet октябрь
A1: 10 | B1: 31 | C1: Басанцова Надежда | D1: 5С | E1: АО "НИИВС "Спектр" | F1: 6 | G1: 6 | H1: 0 | I1: 5 | J1: =IFERROR(I1/G1-H1/G1,"") -> 0.83333333
A2: 10 | B2: 15 | C2: Басанцова Надежда | D2: Картирование | E2: АО "Котлин-Новатор" | F2: 15 | G2: 15 | H2: 0 | I2: 14 | J2: =IFERROR(I2/G2-H2/G2,"") -> 0.93333333
A3: 10 | B3: 30 | C3: Басанцова Надежда | D3: Картирование | E3: АО "НИИВС "Спектр" | F3: 7 | G3: 6 | H3: 0 | I3: 5 | J3: =IFERROR(I3/G3-H3/G3,"") -> 0.83333333
A4: 10 | B4: 8 | C4: Басанцова Надежда | D4: ОБП | E4: ООО "Стройресурс" | F4: 6 | G4: 6 | H4: 0 | I4: 4 | J4: =IFERROR(I4/G4-H4/G4,"") -> 0.66666667
A5: 10 | B5: 28 | C5: Басанцова Надежда | D5: ОБП | E5: АО "НИИВС "Спектр" | F5: 7 | G5: 7 | H5: 0 | I5: 5 | J5: =IFERROR(I5/G5-H5/G5,"") -> 0.71428571
A6: 10 | B6: 15 | C6: Басанцова Надежда | D6: ПА | E6: АО "Котлин-Новатор" | F6: 15 | G6: 15 | H6: 1 | I6: 12 | J6: =IFERROR(I6/G6-H6/G6,"") -> 0.73333333
A7: 10 | B7: 30 | C7: Басанцова Надежда | D7: ПА | E7: АО "НИИВС "Спектр" | F7: 7 | G7: 6 | H7: 0 | I7: 5 | J7: =IFERROR(I7/G7-H7/G7,"") -> 0.83333333
A8: 10 | B8: 31 | C8: Басанцова Надежда | D8: РПУ | E8: АО "НИИВС "Спектр" | F8: 6 | G8: 5 | H8: 0 | I8: 4 | J8: =IFERROR(I8/G8-H8/G8,"") -> 0.8
A9: 10 | B9: 21 | C9: Басанцова Надежда | D9: СР | E9: ООО "ГК Миларин" | F9: 9 | G9: 7 | H9: 0 | I9: 6 | J9: =IFERROR(I9/G9-H9/G9,"") -> 0.85714286
A10: 10 | B10: 16 | C10: Васильева Светлана | D10: 5С | E10: ООО "Стройресурс" | F10: 6 | G10: 5 | H10: 0 | I10: 4 | J10: =IFERROR(I10/G10-H10/G10,"") -> 0.8
A11: 10 | B11: 13 | C11: Васильева Светлана | D11: 5С | E11: ООО "МК Котлин" | F11: 4 | G11: 4 | H11: 0 | I11: 3 | J11: =IFERROR(I11/G11-H11/G11,"") -> 0.75
A12: 10 | B12: 3 | C12: Васильева Светлана | D12: Картирование | E12: ООО "Стройресурс" | F12: 6 | G12: 4 | H12: 0 | I12: 4 | J12: =IFERROR(I12/G12-H12/G12,"") -> 1
... A46: 10 | B46: 7 | C46: Осман Александра | D46: РПУ | E46: ООО "Евролюкс Групп" | F46: 4 | G46: 4 | H46: 0 | I46: 4 | J46: =IFERROR(I46/G46-H46/G46,"") -> 1

Sheet ноябрь
A1: 11 | B1: 6 | C1: Басанцова Надежда | D1: Мет.реш.проблем | E1: ООО "ГК Миларин" | F1: 8 | G1: 6 | H1: 0 | I1: 6 | J1: =IFERROR(I1/G1-H1/G1,"") -> 1
A2: 11 | B2: 26 | C2: Басанцова Надежда | D2: СР | E2: АО "НИИВС "Спектр" | F2: 7 | G2: 7 | H2: 0 | I2: 5 | J2: =IFERROR(I2/G2-H2/G2,"") -> 0.71428571
A3: 11 | B3: 1 | C3: Басанцова Надежда | D3: ОБП | E3: ООО "Нева Тревел Компани" | F3: 6 | G3: 6 | H3: 0 | I3: 5 | J3: =IFERROR(I3/G3-H3/G3,"") -> 0.83333333
A4: 11 | B4: 7 | C4: Басанцова Надежда | D4: РПУ | E4: ООО "Нева Тревел Компани" | F4: 6 | G4: 6 | H4: 0 | I4: 5 | J4: =IFERROR(I4/G4-H4/G4,"") -> 0.83333333
A5: 11 | B5: 7 | C5: Басанцова Надежда | D5: 5С | E5: ООО "Нева Тревел Компани" | F5: 6 | G5: 6 | H5: 0 | I5: 5 | J5: =IFERROR(I5/G5-H5/G5,"") -> 0.83333333
A6: 11 | B6: 10 | C6: Басанцова Надежда | D6: Картирование | E6: ООО "Нева Тревел Компани" | F6: 6 | G6: 5 | H6: 0 | I6: 5 | J6: =IFERROR(I6/G6-H6/G6,"") -> 1
A7: 11 | B7: 10 | C7: Басанцова Надежда | D7: ПА | E7: ООО "Нева Тревел Компани" | F7: 6 | G7: 6 | H7: 0 | I7: 5 | J7: =IFERROR(I7/G7-H7/G7,"") -> 0.83333333
A8: 11 | B8: 21 | C8: Басанцова Надежда | D8: СР | E8: ООО "Нева Тревел Компани" | F8: 6 | G8: 6 | H8: 0 | I8: 5 | J8: =IFERROR(I8/G8-H8/G8,"") -> 0.83333333
A9: 11 | B9: 6 | C9: Васильева Светлана | D9: Мет.реш.проблем | E9: ООО Промстройрегион" | F9: 5 | G9: 5 | H9: 0 | I9: 4 | J9: =IFERROR(I9/G9-H9/G9,"") -> 0.8
A10: 11 | B10: 12 | C10: Васильева Светлана | D10: СР | E10: ООО Промстройрегион" | F10: 5 | G10: 5 | H10: 0 | I10: 5 | J10: =IFERROR(I10/G10-H10/G10,"") -> 1
A11: 11 | B11: 18 | C11: Туранов Кирилл | D11: СР | E11: ООО "Миларин" | F11: 5 | G11: 4 | H11: 0 | I11: 3 | J11: =IFERROR(I11/G11-H11/G11,"") -> 0.75
A12: 11 | B12: 10 | C12: Туранов Кирилл | D12: АО | E12: ООО "Коннектор Системс" | F12: 6 | G12: 6 | H12: 0 | I12: 6 | J12: =IFERROR(I12/G12-H12/G12,"") -> 1
... A34: 11 | B34: 18 | C34: Осман Александра | D34: СР | E34: ООО "СЦ Телрос" | F34: 6 | G34: 6 | H34: 0 | I34: 5 | J34: =IFERROR(I34/G34-H34/G34,"") -> 0.83333333

Sheet декабрь
A1: 12 | B1: 10 | C1: Басанцова Надежда | D1: Мет.реш.проблем | E1: АО "НИИВС "Спектр" | F1: 6 | G1: 6 | H1: 0 | I1: 6 | J1: =IFERROR(I1/G1-H1/G1,"") -> 1
A2: 12 | B2: 2 | C2: Хлебников Александр | D2: СР | E2: ООО "Газпром Геотехнологии" | F2: 7 | G2: 7 | H2: 0 | I2: 6 | J2: =IFERROR(I2/G2-H2/G2,"") -> 0.85714286
A3: 12 | B3: 3 | C3: Басанцова Надежда | D3: СР | E3: ООО "Макро СП" | F3: 5 | G3: 5 | H3: 0 | I3: 5 | J3: =IFERROR(I3/G3-H3/G3,"") -> 1
A4: 12 | B4: 1 | C4: Уваров Константин | D4: СР | E4: ООО "Корпорация Ди энд Ди" | F4: 5 | G4: 5 | H4: 0 | I4: 4 | J4: =IFERROR(I4/G4-H4/G4,"") -> 0.8
A5: 12 | B5: 10 | C5: Уваров Константин | D5: СР | E5: ООО "Метек-Инжиниринг" | F5: 3 | G5: 3 | H5: 0 | I5: 3 | J5: =IFERROR(I5/G5-H5/G5,"") -> 1
A6: 12 | B6: 3 | C6: Хлебников Александр | D6: СР | E6: ООО "МК Котлин" | F6: 5 | G6: 4 | H6: 0 | I6: 3 | J6: =IFERROR(I6/G6-H6/G6,"") -> 0.75
A7: 12 | B7: 1 | C7: Хлебников Александр | D7: СР | E7: ООО "Стройресурс" | F7: 5 | G7: 5 | H7: 0 | I7: 5 | J7: =IFERROR(I7/G7-H7/G7,"") -> 1
A8: 12 | B8: 9 | C8: Уваров Константин | D8: СР | E8: АО "НЭО" | F8: 5 | G8: 4 | H8: 0 | I8: 4 | J8: =IFERROR(I8/G8-H8/G8,"") -> 1
